Workbook

Sheet Checklist
A1: Phase | B1: # | C1: Priority | D1: Domain | E1: Task | F1: Type | G1: Resource (click to open) | H1: Est (h) | I1: Status | J1: Date done | K1: Notes
A2: P0 - Orient | B2: 1 | C2: HIGH | D2: ALL | E2: Read the kit README, then skim the official links index so you know where everything lives | F2: Setup | G2: 01 - Official links index | H2: 0.3 | I2: Not Started
A3: P0 - Orient | B3: 2 | C3: HIGH | D3: ALL | E3: Download the official Exam Guide PDF; do all 12 sample questions reading every wrong-answer rationale | F3: Docs | G3: Skilljar - CCA-F certification page | H3: 1.5 | I3: Not Started | K3: 60 questions / 120 min / passing score 720. Domain weights: D1 27, D3 20, D4 20, D2 18, D5 15 (%)
A4: P0 - Orient | B4: 3 | C4: MED | D4: ALL | E4: Read the exam-day one-pager once now (you will reread it in the final 24h) | F4: Strategy | G4: 05 - Exam-day one-pager | H4: 0.3 | I4: Not Started | K4: The enforcement ladder and wrong-answer tells frame everything that follows
A5: P1 - D1 Agentic Architecture | B5: 4 | C5: HIGH | D5: D1 | E5: Baseline drill: D1 filter, 5 questions; note which misses were honeypots | F5: Drill | G5: 02 - Honeypot drill (open in browser) | H5: 0.4 | I5: Not Started
A6: P1 - D1 Agentic Architecture | B6: 5 | C6: HIGH | D6: D1 | E6: Read: Building effective agents - workflows vs agents; the five workflow patterns incl. orchestrator-workers | F6: Article | G6: Anthropic engineering post | H6: 0.8 | I6: Not Started | K6: Covers the tested objectives on orchestration pattern selection and when-to-build-an-agent
A7: P1 - D1 Agentic Architecture | B7: 6 | C7: HIGH | D7: D1 | E7: Read: How we built our multi-agent research system | F7: Article | G7: Anthropic engineering post | H7: 0.8 | I7: Not Started | K7: Covers subagent prompt completeness, checkpoints / state persistence, resume-on-error, orchestrator-worker in production - all tested objectives
A8: P1 - D1 Agentic Architecture | B8: 7 | C8: HIGH | D8: D1 | E8: Docs: Tool use overview - the agent loop, stop_reason values, parallel tool use | F8: Docs | G8: Docs - Tool use overview | H8: 0.8 | I8: Not Started | K8: Loop control: stop_reason drives everything; NL-parsing and iteration caps are wrong-answer tells
A9: P1 - D1 Agentic Architecture | B9: 8 | C9: MED | D9: D1 | E9: Docs: Subagents in Claude Code - context isolation, tool restrictions, spawning | F9: Docs | G9: Code docs - Subagents | H9: 0.5 | I9: Not Started | K9: Subagents inherit nothing from the parent; spawn prompts must be complete
A10: P1 - D1 Agentic Architecture | B10: 9 | C10: HIGH | D10: D1 | E10: Lab 10: Orchestrator-worker isolation & provenance | F10: Lab | G10: 03 - Labs index (domain-labs.md) | H10: 0.8 | I10: Not Started
A11: P1 - D1 Agentic Architecture | B11: 10 | C11: HIGH | D11: D1 | E11: Lab 11: The agent loop done right | F11: Lab | G11: 03 - Labs index (domain-labs.md) | H11: 0.7 | I11: Not Started
A12: P1 - D1 Agentic Architecture | B12: 11 | C12: HIGH | D12: D1 | E12: Lab 12: Agent design judgment - tiering, error contracts, escalation | F12: Lab | G12: 03 - Labs index (domain-labs.md) | H12: 0.7 | I12: Not Started
A13: P1 - D1 Agentic Architecture | B13: 12 | C13: HIGH | D13: D1 | E13: Re-drill D1 the next day; must hold 5/5, else revisit rationales | F13: Drill | G13: 02 - Honeypot drill (open in browser) | H13: 0.3 | I13: Not Started
A14: P2 - D2 Tool Design & MCP | B14: 13 | C14: HIGH | D14: D2 | E14: Baseline drill: D2 filter, 5 questions | F14: Drill | G14: 02 - Honeypot drill (open in browser) | H14: 0.4 | I14: Not Started
A15: P2 - D2 Tool Design & MCP | B15: 14 | C15: HIGH | D15: D2 | E15: Docs: Tool use overview - descriptions / when-to-call, tool_choice modes, strict | F15: Docs | G15: Docs - Tool use overview | H15: 0.8 | I15: Not Started | K15: Same page as the D1 pass; this pass focuses on tool descriptions, tool_choice and strict
A16: P2 - D2 Tool Design & MCP | B16: 15 | C16: HIGH | D16: D2 | E16: Docs: MCP in Claude Code - scopes (local/project/user), env-var expansion, /mcp, auth | F16: Docs | G16: Code docs - MCP | H16: 0.7 | I16: Not Started | K16: Also know MCP resources vs tools (tested); concepts at modelcontextprotocol.io
A17: P2 - D2 Tool Design & MCP | B17: 16 | C17: MED | D17: D2 | E17: Courses: Intro to MCP + MCP Advanced Topics | F17: Course | G17: Academy - Intro to MCP | H17: 1.5 | I17: Not Started
A18: P2 - D2 Tool Design & MCP | B18: 17 | C18: HIGH | D18: D2 | E18: Lab 13: Tool definitions that trigger correctly | F18: Lab | G18: 03 - Labs index (domain-labs.md) | H18: 0.6 | I18: Not Started
A19: P2 - D2 Tool Design & MCP | B19: 18 | C19: HIGH | D19: D2 | E19: Lab 14: Scoped tools & parallel execution | F19: Lab | G19: 03 - Labs index (domain-labs.md) | H19: 0.6 | I19: Not Started
A20: P2 - D2 Tool Design & MCP | B20: 19 | C20: MED | D20: D2 | E20: Lab 15: MCP integration (needs Node / npx) | F20: Lab | G20: 03 - Labs index (domain-labs.md) | H20: 0.7 | I20: Not Started
A21: P2 - D2 Tool Design & MCP | B21: 20 | C21: HIGH | D21: D2 | E21: Re-drill D2; must hold 5/5 | F21: Drill | G21: 02 - Honeypot drill (open in browser) | H21: 0.3 | I21: Not Started
A22: P3 - D3 Claude Code Config | B22: 21 | C22: HIGH | D22: D3 | E22: Baseline drill: D3 filter, 5 questions | F22: Drill | G22: 02 - Honeypot drill (open in browser) | H22: 0.4 | I22: Not Started
A23: P3 - D3 Claude Code Config | B23: 22 | C23: HIGH | D23: D3 | E23: Docs: Extend Claude Code - when to use CLAUDE.md vs rules vs skills vs subagents vs hooks vs MCP | F23: Docs | G23: Code docs - Extend Claude Code | H23: 0.5 | I23: Not Started | K23: Directly covers the tested config-mechanism-selection objective
A24: P3 - D3 Claude Code Config | B24: 23 | C24: HIGH | D24: D3 | E24: Docs: Memory - CLAUDE.md hierarchy (managed/user/project), subdirectory loading, @imports, .claude/rules/ with paths globs | F24: Docs | G24: Code docs - Memory | H24: 0.8 | I24: Not Started | K24: Tip: set CLAUDE_CODE_NEW_INIT=1 for the interactive multi-phase /init flow
A25: P3 - D3 Claude Code Config | B25: 24 | C25: HIGH | D25: D3 | E25: Docs: Hooks - events, matchers, exit codes (PreToolUse exit 2 blocks) | F25: Docs | G25: Code docs - Hooks | H25: 0.8 | I25: Not Started
A26: P3 - D3 Claude Code Config | B26: 25 | C26: HIGH | D26: D3 | E26: Docs: Skills - SKILL.md frontmatter, progressive disclosure, triggering | F26: Docs | G26: Code docs - Skills | H26: 0.7 | I26: Not Started | K26: Tip: study the skill-creator skill as a worked example of good frontmatter
A27: P3 - D3 Claude Code Config | B27: 26 | C27: MED | D27: D3 | E27: Docs: Slash commands vs skills - when you invoke vs when Claude does | F27: Docs | G27: Code docs - Slash commands | H27: 0.4 | I27: Not Started
A28: P3 - D3 Claude Code Config | B28: 27 | C28: HIGH | D28: D3 | E28: Docs: Settings and permissions - allow/deny rules, settings scopes | F28: Docs | G28: Code docs - Settings | H28: 0.6 | I28: Not Started | K28: Tip: the $schema line in settings.json enables autocomplete + inline validation in editors
A29: P3 - D3 Claude Code Config | B29: 28 | C29: HIGH | D29: D3 | E29: Docs: Permission modes incl. plan mode - plan vs direct execution vs multi-phase review | F29: Docs | G29: Code docs - Permission modes | H29: 0.5 | I29: Not Started | K29: Covers the tested review-architecture objective: choose by task scope, risk level, approval requirements
A30: P3 - D3 Claude Code Config | B30: 29 | C30: HIGH | D30: D3 | E30: Docs: CLI reference + Headless - -p, --output-format json, --resume, --bare, --tools vs --allowedTools | F30: Docs | G30: Code docs - CLI reference | H30: 0.6 | I30: Not Started | K30: Field-note exam question: slow scripted startup -> --bare + --allowedTools (see exam-strategy one-pager); headless page: code.claude.com/docs/en/headless
A31: P3 - D3 Claude Code Config | B31: 30 | C31: HIGH | D31: D3 | E31: Docs: Tools reference + Common workflows - Grep vs Glob vs Read vs Bash; incremental codebase exploration | F31: Docs | G31: Code docs - Tools reference | H31: 0.7 | I31: Not Started | K31: Covers the tested built-in-tool-selection + exploration-strategy objectives; workflows: code.claude.com/docs/en/common-workflows
A32: P3 - D3 Claude Code Config | B32: 31 | C32: MED | D32: D3 | E32: Docs: Sessions (--continue/--resume scope rules) + Code review configuration | F32: Docs | G32: Code docs - Sessions | H32: 0.5 | I32: Not Started | K32: Review configs (standards, tool restriction, structured output) are a tested objective; see code.claude.com/docs/en/code-review
A33: P3 - D3 Claude Code Config | B33: 32 | C33: HIGH | D33: D3 | E33: Lab 4: Memory hierarchy walk + skill triggering | F33: Lab | G33: 03 - Labs index (domain-labs.md) | H33: 0.7 | I33: Not Started
A34: P3 - D3 Claude Code Config | B34: 33 | C34: HIGH | D34: D3 | E34: Lab 5: Enforcement, not exhortation (highest-yield lab in the kit) | F34: Lab | G34: 03 - Labs index (domain-labs.md) | H34: 0.7 | I34: Not Started
A35: P3 - D3 Claude Code Config | B35: 34 | C35: HIGH | D35: D3 | E35: Lab 6: Headless CI with generator/reviewer isolation | F35: Lab | G35: 03 - Labs index (domain-labs.md) | H35: 0.8 | I35: Not Started
A36: P3 - D3 Claude Code Config | B36: 35 | C36: MED | D36: D3 | E36: Courses: Claude Code in Action; Intro to Agent Skills; Intro to Subagents | F36: Course | G36: Academy - course catalog | H36: 2.5 | I36: Not Started
A37: P3 - D3 Claude Code Config | B37: 36 | C37: MED | D37: D3 | E37: Docs: GitHub Actions integration (CI scenario) | F37: Docs | G37: Code docs - GitHub Actions | H37: 0.4 | I37: Not Started
A38: P3 - D3 Claude Code Config | B38: 37 | C38: HIGH | D38: D3 | E38: Re-drill D3; must hold 5/5 | F38: Drill | G38: 02 - Honeypot drill (open in browser) | H38: 0.3 | I38: Not Started
A39: P4 - D4 Prompt Eng & Output | B39: 38 | C39: HIGH | D39: D4 | E39: Baseline drill: D4 filter, 5 questions | F39: Drill | G39: 02 - Honeypot drill (open in browser) | H39: 0.4 | I39: Not Started
A40: P4 - D4 Prompt Eng & Output | B40: 39 | C40: HIGH | D40: D4 | E40: Study Prompting best practices end to end (examples, chaining, agentic prompting) | F40: Docs | G40: Docs - Prompting best practices | H40: 1.2 | I40: Not Started
...

Sheet Dashboard
A1: CCA-F Prep Dashboard
A3: Overall progress | B3: =COUNTIF(Checklist!$I$2:$I$61,"Done")/60 -> 0 | C3: Hours remaining | D3: =SUMIFS(Checklist!$H$2:$H$61,Checklist!$I$2:$I$61,"<>Done") -> 45.4
A5: Progress by phase
A6: Phase | B6: Done | C6: Total | D6: Progress
A7: P0 - Orient | B7: =COUNTIFS(Checklist!$A$2:$A$61,A7,Checklist!$I$2:$I$61,"Done") -> 0 | C7: =COUNTIF(Checklist!$A$2:$A$61,A7) -> 3 | D7: =IF(C7=0,0,B7/C7) -> 0
A8: P1 - D1 Agentic Architecture | B8: =COUNTIFS(Checklist!$A$2:$A$61,A8,Checklist!$I$2:$I$61,"Done") -> 0 | C8: =COUNTIF(Checklist!$A$2:$A$61,A8) -> 9 | D8: =IF(C8=0,0,B8/C8) -> 0
A9: P2 - D2 Tool Design & MCP | B9: =COUNTIFS(Checklist!$A$2:$A$61,A9,Checklist!$I$2:$I$61,"Done") -> 0 | C9: =COUNTIF(Checklist!$A$2:$A$61,A9) -> 8 | D9: =IF(C9=0,0,B9/C9) -> 0
A10: P3 - D3 Claude Code Config | B10: =COUNTIFS(Checklist!$A$2:$A$61,A10,Checklist!$I$2:$I$61,"Done") -> 0 | C10: =COUNTIF(Checklist!$A$2:$A$61,A10) -> 17 | D10: =IF(C10=0,0,B10/C10) -> 0
A11: P4 - D4 Prompt Eng & Output | B11: =COUNTIFS(Checklist!$A$2:$A$61,A11,Checklist!$I$2:$I$61,"Done") -> 0 | C11: =COUNTIF(Checklist!$A$2:$A$61,A11) -> 9 | D11: =IF(C11=0,0,B11/C11) -> 0
A12: P5 - D5 Context & Reliability | B12: =COUNTIFS(Checklist!$A$2:$A$61,A12,Checklist!$I$2:$I$61,"Done") -> 0 | C12: =COUNTIF(Checklist!$A$2:$A$61,A12) -> 8 | D12: =IF(C12=0,0,B12/C12) -> 0
A13: P6 - Final Prep | B13: =COUNTIFS(Checklist!$A$2:$A$61,A13,Checklist!$I$2:$I$61,"Done") -> 0 | C13: =COUNTIF(Checklist!$A$2:$A$61,A13) -> 6 | D13: =IF(C13=0,0,B13/C13) -> 0
A16: Progress by domain
A17: Domain | B17: Done | C17: Total | D17: Progress | E17: Exam weight
A18: D1 - Agentic Architecture & Orchestration | B18: =COUNTIFS(Checklist!$D$2:$D$61,"D1",Checklist!$I$2:$I$61,"Done") -> 0 | C18: =COUNTIF(Checklist!$D$2:$D$61,"D1") -> 9 | D18: =IF(C18=0,0,B18/C18) -> 0 | E18: 0.27
A19: D2 - Tool Design & MCP Integration | B19: =COUNTIFS(Checklist!$D$2:$D$61,"D2",Checklist!$I$2:$I$61,"Done") -> 0 | C19: =COUNTIF(Checklist!$D$2:$D$61,"D2") -> 8 | D19: =IF(C19=0,0,B19/C19) -> 0 | E19: 0.18
A20: D3 - Claude Code Config & Workflows | B20: =COUNTIFS(Checklist!$D$2:$D$61,"D3",Checklist!$I$2:$I$61,"Done") -> 0 | C20: =COUNTIF(Checklist!$D$2:$D$61,"D3") -> 17 | D20: =IF(C20=0,0,B20/C20) -> 0 | E20: 0.2
A21: D4 - Prompt Eng & Structured Output | B21: =COUNTIFS(Checklist!$D$2:$D$61,"D4",Checklist!$I$2:$I$61,"Done") -> 0 | C21: =COUNTIF(Checklist!$D$2:$D$61,"D4") -> 9 | D21: =IF(C21=0,0,B21/C21) -> 0 | E21: 0.2
A22: D5 - Context Mgmt & Reliability | B22: =COUNTIFS(Checklist!$D$2:$D$61,"D5",Checklist!$I$2:$I$61,"Done") -> 0 | C22: =COUNTIF(Checklist!$D$2:$D$61,"D5") -> 8 | D22: =IF(C22=0,0,B22/C22) -> 0 | E22: 0.15
A23: Cross-domain (orient + final prep) | B23: =COUNTIFS(Checklist!$D$2:$D$61,"ALL",Checklist!$I$2:$I$61,"Done") -> 0 | C23: =COUNTIF(Checklist!$D$2:$D$61,"ALL") -> 9 | D23: =IF(C23=0,0,B23/C23) -> 0
A26: How to use
A27: 1. Work the Checklist tab top to bottom: P0 orientation, then one domain phase at a time (D1 through D5, ordered by domain number), then P6 final prep.
A28: 2. Edit ONLY the three input columns: Status (dropdown), Date done, and Notes. Every other cell, and this dashboard, is formula-driven.
A29: 3. Example entry: when you finish a task, set Status = Done and Date done = 2026-07-15 (any date format works); the row tints green and the Dashboard updates.
A30: 4. Status colors: green = Done, amber = In Progress. Red priority text = HIGH.
A31: 5. Resource links open docs and courses online; drill, labs, and strategy links open local files in this kit (keep the workbook in the kit's root folder).
A32: 6. Lab answer keys live in 03-Hands-On-Labs/_AnswerKeys/ - attempt each lab before opening its key.

Sheet Objective Map
A1: Exam objective coverage map
A2: Test objectives from the official exam blueprint (as reported section-wise on score reports). Each objective is mapped to where this kit covers it; doc coverage verified against the linked pages (July 2026).
A4: # | B4: Domain | C4: Exam objective | D4: Covered in this kit by | E4: Primary reference (click to open)
A5: 1 | B5: D1 | C5: Configure agentic loops to emit multiple tool calls within a single response turn, enabling parallel execution of independent subtasks and reducing total round-trip latency. | D5: Lab 11 step 4 - Lab 14 step 3 - Drill Q16 | E5: Tool use overview
A6: 2 | B6: D1 | C6: Apply session resumption techniques - including targeted re-analysis of changed files and context injection - to restore agent state accurately without repeating prior work. | D6: Checklist P3 Sessions row - Strategy sheet 'State persistence' | E6: Sessions
A7: 3 | B7: D1 | C7: Construct subagent prompts that include all findings, structured data, and source metadata required for task completion without returning to the coordinator for missing context. | D7: Lab 10 steps 1-2 - Drill Q17 | E7: How we built our multi-agent research system
A8: 4 | B8: D1 | C8: Evaluate subagent delegation strategies - goal-oriented versus procedural instructions - and select the approach that enables adaptive behavior while maintaining coordinator visibility and control. | D8: Strategy sheet 'Multi-agent' (delegation style) | E8: Multi-agent research post ('Teach the orchestrator how to delegate')
A9: 5 | B9: D1 | C9: Configure subagent invocations with appropriate tool restrictions, context scoping, and system prompts that constrain each agent to its designated role. | D9: Lab 10 - Lab 14 - Drill Q23 | E9: Subagents in Claude Code
A10: 6 | B10: D1 | C10: Diagnose misconfigured subagent spawning by identifying missing tool permissions, incorrect AgentDefinition parameters, or absent coordinator-to-subagent wiring. | D10: Official links index (D1 section) | E10: Subagents in the Agent SDK
A11: 7 | B11: D1 | C11: Decompose complex tasks into dynamically generated subtasks that adapt as new information is discovered, rather than executing a fixed sequence regardless of intermediate findings. | D11: Drill Q18 - Lab 10 | E11: Building effective agents (orchestrator-workers)
A12: 8 | B12: D3 | C12: Select the appropriate agentic review architecture - plan mode, direct execution, or multi-phase workflow - based on task scope, risk level, and human approval requirements. | D12: Checklist P3 Permission-modes row - Strategy sheet 'Review architecture' | E12: Permission modes (incl. plan mode)
A13: 9 | B13: D1 | C13: Design state persistence strategies for multi-agent pipelines that enable reliable resumption after interruption without repeating completed work or losing prior findings. | D13: Drill Q19 - Strategy sheet 'State persistence' | E13: Multi-agent research post (checkpoints, resume-on-error)
A14: 10 | B14: D1 | C14: Evaluate multi-agent orchestration patterns - coordinator-worker, parallel execution, and sequential pipelines - to select the structure best satisfying research coverage, latency, and reliability requirements. | D14: Drill Q18 - Lab 10 | E14: Building effective agents (the five workflow patterns)
A15: 11 | B15: D3 | C15: Configure Claude Code CLI invocations for automated CI/CD pipelines using non-interactive flags, permission modes, and cost and turn limits that prevent runaway executions. | D15: Lab 6 - Drill Q9 - Strategy sheet field note (--bare) | E15: CLI reference + Headless
A16: 12 | B16: D4 | C16: Structure iterative refinement workflows by providing concrete input-output examples, targeted feedback on specific failures, and batched issue descriptions for consolidated evaluation. | D16: Lab 3 (validation-retry, targeted feedback) | E16: Prompting best practices
... A41: 37 | B41: D2 | C41: Configure the tool_choice parameter to guarantee tool invocation when structured output is required, and sequence multi-tool workflows so prerequisite data is obtained before dependent tools are called. | D41: Lab 13 step 2 - Drill Q22 | E41: Tool use overview
